Traceback (most recent call last):
  File "/Users/kstlaurent/anaconda3/envs/SCDA2/lib/python3.6/warnings.py", line 164, in _add_filter
    filters.remove(item)
ValueError: list.remove(x): x not in list

During handling of the above exception, another exception occurred:

Traceback (most recent call last):
  File "/user/kstlaurent/git/progressive_refinement_coronagraphy/surveys/luvoir_N0200_small_local/drivers/13_LUVOIR_N200_FPM382M050_IWA0325_OWA01200_C10_BW18_Nlam8_LS_IDD0195_OD0965_no_ls_struts.py", line 5, in <module>
    from hcipy import *
  File "/Users/kstlaurent/git/hcipy/hcipy/__init__.py", line 2, in <module>
    from . import aperture
  File "/Users/kstlaurent/git/hcipy/hcipy/aperture/__init__.py", line 4, in <module>
    from .generic import *
  File "/Users/kstlaurent/git/hcipy/hcipy/aperture/generic.py", line 2, in <module>
    import numpy as np
  File "/Users/kstlaurent/anaconda3/envs/SCDA2/lib/python3.6/site-packages/numpy/__init__.py", line 187, in <module>
    warnings.filterwarnings("ignore", message="numpy.ndarray size changed")
  File "/Users/kstlaurent/anaconda3/envs/SCDA2/lib/python3.6/warnings.py", line 141, in filterwarnings
    re.compile(module), lineno, append=append)
  File "/Users/kstlaurent/anaconda3/envs/SCDA2/lib/python3.6/warnings.py", line 164, in _add_filter
    filters.remove(item)
KeyboardInterrupt
